[2024-10-16T02:12:56.569+0000] {local_task_job_runner.py:123} INFO - ::group::Pre task execution logs
[2024-10-16T02:12:56.577+0000] {taskinstance.py:2612} INFO - Dependencies all met for dep_context=non-requeueable deps ti=<TaskInstance: simple_dag.print_hello_world manual__2024-10-16T02:12:56.189127+00:00 [queued]>
[2024-10-16T02:12:56.582+0000] {taskinstance.py:2612} INFO - Dependencies all met for dep_context=requeueable deps ti=<TaskInstance: simple_dag.print_hello_world manual__2024-10-16T02:12:56.189127+00:00 [queued]>
[2024-10-16T02:12:56.582+0000] {taskinstance.py:2865} INFO - Starting attempt 1 of 2
[2024-10-16T02:12:56.589+0000] {taskinstance.py:2888} INFO - Executing <Task(PythonOperator): print_hello_world> on 2024-10-16 02:12:56.189127+00:00
[2024-10-16T02:12:56.593+0000] {standard_task_runner.py:104} INFO - Running: ['***', 'tasks', 'run', 'simple_dag', 'print_hello_world', 'manual__2024-10-16T02:12:56.189127+00:00', '--job-id', '9', '--raw', '--subdir', 'DAGS_FOLDER/chinedu_message.py', '--cfg-path', '/tmp/tmp2iecnf74']
[2024-10-16T02:12:56.594+0000] {logging_mixin.py:190} WARNING - /home/***/.local/lib/python3.12/site-packages/***/task/task_runner/standard_task_runner.py:70 DeprecationWarning: This process (pid=4988) is multi-threaded, use of fork() may lead to deadlocks in the child.
[2024-10-16T02:12:56.595+0000] {standard_task_runner.py:105} INFO - Job 9: Subtask print_hello_world
[2024-10-16T02:12:56.595+0000] {standard_task_runner.py:72} INFO - Started process 4989 to run task
[2024-10-16T02:12:56.623+0000] {task_command.py:467} INFO - Running <TaskInstance: simple_dag.print_hello_world manual__2024-10-16T02:12:56.189127+00:00 [running]> on host f574f9bad4ca
[2024-10-16T02:12:56.660+0000] {taskinstance.py:3131} INFO - Exporting env vars: AIRFLOW_CTX_DAG_OWNER='***' AIRFLOW_CTX_DAG_ID='simple_dag' AIRFLOW_CTX_TASK_ID='print_hello_world' AIRFLOW_CTX_EXECUTION_DATE='2024-10-16T02:12:56.189127+00:00' AIRFLOW_CTX_TRY_NUMBER='1' AIRFLOW_CTX_DAG_RUN_ID='manual__2024-10-16T02:12:56.189127+00:00'
[2024-10-16T02:12:56.661+0000] {logging_mixin.py:190} INFO - Task instance is in running state
[2024-10-16T02:12:56.662+0000] {logging_mixin.py:190} INFO -  Previous state of the Task instance: queued
[2024-10-16T02:12:56.662+0000] {logging_mixin.py:190} INFO - Current task name:print_hello_world state:running start_date:2024-10-16 02:12:56.578051+00:00
[2024-10-16T02:12:56.662+0000] {logging_mixin.py:190} INFO - Dag name:simple_dag and current dag run status:running
[2024-10-16T02:12:56.662+0000] {taskinstance.py:731} INFO - ::endgroup::
[2024-10-16T02:12:56.663+0000] {logging_mixin.py:190} INFO - Hello, Airflow!
[2024-10-16T02:12:56.663+0000] {python.py:240} INFO - Done. Returned value was: None
[2024-10-16T02:12:56.667+0000] {taskinstance.py:340} INFO - ::group::Post task execution logs
[2024-10-16T02:12:56.667+0000] {taskinstance.py:352} INFO - Marking task as SUCCESS. dag_id=simple_dag, task_id=print_hello_world, run_id=manual__2024-10-16T02:12:56.189127+00:00, execution_date=20241016T021256, start_date=20241016T021256, end_date=20241016T021256
[2024-10-16T02:12:56.668+0000] {taskinstance.py:1563} INFO - Executing callback at index 0: <lambda>
[2024-10-16T02:12:56.670+0000] {taskinstance.py:1567} ERROR - Error in callback at index 0: <lambda>
Traceback (most recent call last):
  File "/home/airflow/.local/lib/python3.12/site-packages/urllib3/connection.py", line 196, in _new_conn
    sock = connection.create_connection(
           ^^^^^^^^^^^^^^^^^^^^^^^^^^^^^
  File "/home/airflow/.local/lib/python3.12/site-packages/urllib3/util/connection.py", line 85, in create_connection
    raise err
  File "/home/airflow/.local/lib/python3.12/site-packages/urllib3/util/connection.py", line 73, in create_connection
    sock.connect(sa)
ConnectionRefusedError: [Errno 111] Connection refused

The above exception was the direct cause of the following exception:

Traceback (most recent call last):
  File "/home/airflow/.local/lib/python3.12/site-packages/urllib3/connectionpool.py", line 789, in urlopen
    response = self._make_request(
               ^^^^^^^^^^^^^^^^^^^
  File "/home/airflow/.local/lib/python3.12/site-packages/urllib3/connectionpool.py", line 495, in _make_request
    conn.request(
  File "/home/airflow/.local/lib/python3.12/site-packages/urllib3/connection.py", line 398, in request
    self.endheaders()
  File "/usr/local/lib/python3.12/http/client.py", line 1331, in endheaders
    self._send_output(message_body, encode_chunked=encode_chunked)
  File "/usr/local/lib/python3.12/http/client.py", line 1091, in _send_output
    self.send(msg)
  File "/usr/local/lib/python3.12/http/client.py", line 1035, in send
    self.connect()
  File "/home/airflow/.local/lib/python3.12/site-packages/urllib3/connection.py", line 236, in connect
    self.sock = self._new_conn()
                ^^^^^^^^^^^^^^^^
  File "/home/airflow/.local/lib/python3.12/site-packages/urllib3/connection.py", line 211, in _new_conn
    raise NewConnectionError(
urllib3.exceptions.NewConnectionError: <urllib3.connection.HTTPConnection object at 0xffff7d472180>: Failed to establish a new connection: [Errno 111] Connection refused

The above exception was the direct cause of the following exception:

Traceback (most recent call last):
  File "/home/airflow/.local/lib/python3.12/site-packages/requests/adapters.py", line 667, in send
    resp = conn.urlopen(
           ^^^^^^^^^^^^^
  File "/home/airflow/.local/lib/python3.12/site-packages/urllib3/connectionpool.py", line 843, in urlopen
    retries = retries.increment(
              ^^^^^^^^^^^^^^^^^^
  File "/home/airflow/.local/lib/python3.12/site-packages/urllib3/util/retry.py", line 519, in increment
    raise MaxRetryError(_pool, url, reason) from reason  # type: ignore[arg-type]
    ^^^^^^^^^^^^^^^^^^^^^^^^^^^^^^^^^^^^^^^^^^^^^^^^^^^
urllib3.exceptions.MaxRetryError: HTTPConnectionPool(host='localhost', port=3000): Max retries exceeded with url: /hooks/670f20e6a7c2b992c2cc4964/EMxu3ghBeH9PAatGBEeXWwoG6wfHozsG7s3GqEjDLQfy5DLs (Caused by NewConnectionError('<urllib3.connection.HTTPConnection object at 0xffff7d472180>: Failed to establish a new connection: [Errno 111] Connection refused'))

During handling of the above exception, another exception occurred:

Traceback (most recent call last):
  File "/home/airflow/.local/lib/python3.12/site-packages/airflow/models/taskinstance.py", line 1565, in _run_finished_callback
    callback(context)
  File "/opt/airflow/dags/chinedu_message.py", line 63, in <lambda>
    on_success_callback=lambda context: configure_rocketchat_success_alert(context,'Testing...the task was successful.' ),
                                        ^^^^^^^^^^^^^^^^^^^^^^^^^^^^^^^^^^^^^^^^^^^^^^^^^^^^^^^^^^^^^^^^^^^^^^^^^^^^^^^^^
  File "/opt/airflow/dags/chinedu_message.py", line 32, in configure_rocketchat_success_alert
    response = requests.post(webhook_url, data=json.dumps(payload),
               ^^^^^^^^^^^^^^^^^^^^^^^^^^^^^^^^^^^^^^^^^^^^^^^^^^^^
  File "/home/airflow/.local/lib/python3.12/site-packages/requests/api.py", line 115, in post
    return request("post", url, data=data, json=json, **kwargs)
           ^^^^^^^^^^^^^^^^^^^^^^^^^^^^^^^^^^^^^^^^^^^^^^^^^^^^
  File "/home/airflow/.local/lib/python3.12/site-packages/requests/api.py", line 59, in request
    return session.request(method=method, url=url, **kwargs)
           ^^^^^^^^^^^^^^^^^^^^^^^^^^^^^^^^^^^^^^^^^^^^^^^^^
  File "/home/airflow/.local/lib/python3.12/site-packages/requests/sessions.py", line 589, in request
    resp = self.send(prep, **send_kwargs)
           ^^^^^^^^^^^^^^^^^^^^^^^^^^^^^^
  File "/home/airflow/.local/lib/python3.12/site-packages/requests/sessions.py", line 703, in send
    r = adapter.send(request, **kwargs)
        ^^^^^^^^^^^^^^^^^^^^^^^^^^^^^^^
  File "/home/airflow/.local/lib/python3.12/site-packages/requests/adapters.py", line 700, in send
    raise ConnectionError(e, request=request)
requests.exceptions.ConnectionError: HTTPConnectionPool(host='localhost', port=3000): Max retries exceeded with url: /hooks/670f20e6a7c2b992c2cc4964/EMxu3ghBeH9PAatGBEeXWwoG6wfHozsG7s3GqEjDLQfy5DLs (Caused by NewConnectionError('<urllib3.connection.HTTPConnection object at 0xffff7d472180>: Failed to establish a new connection: [Errno 111] Connection refused'))
[2024-10-16T02:12:56.678+0000] {logging_mixin.py:190} INFO - Task instance in success state
[2024-10-16T02:12:56.679+0000] {logging_mixin.py:190} INFO -  Previous state of the Task instance: running
[2024-10-16T02:12:56.679+0000] {logging_mixin.py:190} INFO - Dag name:simple_dag queued_at:2024-10-16 02:12:56.197047+00:00
[2024-10-16T02:12:56.679+0000] {logging_mixin.py:190} INFO - Task hostname:f574f9bad4ca operator:PythonOperator
[2024-10-16T02:12:56.693+0000] {local_task_job_runner.py:266} INFO - Task exited with return code 0
[2024-10-16T02:12:56.701+0000] {taskinstance.py:3900} INFO - 0 downstream tasks scheduled from follow-on schedule check
[2024-10-16T02:12:56.702+0000] {local_task_job_runner.py:245} INFO - ::endgroup::
